<?xml version="1.0" ?>
<!-- =================================================================================== -->
<!-- |    This document was autogenerated by xacro from xacro/joint_rope.xacro         | -->
<!-- |    EDITING THIS FILE BY HAND IS NOT RECOMMENDED                                 | -->
<!-- =================================================================================== -->
<robot name="rope" xmlns:xacro="http://www.ros.org/wiki/xacro">
  <joint name="j_" type="revolute">
    <limit effort="5" lower="-0.785" upper="0.785" velocity="6.28"/>
    <parent link="rope_seg_"/>
    <child link="rope_seg_"/>
    <origin xyz="0 0 0.01"/>
    <axis xyz="1 0 0"/>
    <dynamics damping="2" friction="0.1"/>
  </joint>
</robot>

