<?xml version="1.0" ?>
<!-- =================================================================================== -->
<!-- |    This document was autogenerated by xacro from xacro/segment_rope.xacro       | -->
<!-- |    EDITING THIS FILE BY HAND IS NOT RECOMMENDED                                 | -->
<!-- =================================================================================== -->
<robot name="rope" xmlns:xacro="http://www.ros.org/wiki/xacro">
  <link name="rope_seg_1">
    <visual>
      <geometry>
        <cylinder length="0.01" radius="0.002"/>
      </geometry>
    </visual>
    <collision>
      <geometry>
        <cylinder length="0.01" radius="0.002"/>
      </geometry>
    </collision>
    <inertial>
      <mass value="0.01"/>
      <inertia ixx="1.0" ixy="0.0" ixz="0.0" iyy="1.0" iyz="0.0" izz="1.0"/>
    </inertial>
  </link>
  <gazebo reference="rope_seg_1">
    <material>Gazebo/Blue</material>
  </gazebo>
  <link name="rope_seg_2">
    <visual>
      <geometry>
        <cylinder length="0.01" radius="0.002"/>
      </geometry>
    </visual>
    <collision>
      <geometry>
        <cylinder length="0.01" radius="0.002"/>
      </geometry>
    </collision>
    <inertial>
      <mass value="0.01"/>
      <inertia ixx="1.0" ixy="0.0" ixz="0.0" iyy="1.0" iyz="0.0" izz="1.0"/>
    </inertial>
  </link>
  <gazebo reference="rope_seg_2">
    <material>Gazebo/Red</material>
  </gazebo>
  <joint name="j1" type="revolute">
    <limit effort="5" lower="-0.785" upper="0.785" velocity="6.28"/>
    <parent link="rope_seg_1"/>
    <child link="rope_seg_2"/>
    <origin xyz="0 0 0.01"/>
    <axis xyz="1 0 0"/>
    <dynamics damping="2" friction="0.1"/>
  </joint>
</robot>

