<?xml version="1.0"?>
<robot xmlns:xacro="http://www.ros.org/wiki/xacro" name="rope">

<xacro:property name="length" value="0.01" />
<xacro:property name="radius" value="0.002" />
<xacro:property name="link_name" value="rope_seg_"/>
<xacro:property name="mass" value="0.01"/>

<xacro:property name="effort" value="5"/>
<xacro:property name="velocity" value="6.28"/>
<xacro:property name="lower" value="-0.785"/>
<xacro:property name="upper" value="0.785"/>
<xacro:property name="damping" value="2"/>
<xacro:property name="friction" value="0.1"/>

<xacro:property name="axis_x" value="1"/>
<xacro:property name="axis_y" value="0"/>
<xacro:property name="axis_z" value="0"/>
     
<xacro:macro name="link_description" params="link_number color">
        <link name="${link_name}${link_number}">
                <visual>
                        <geometry>
                                <cylinder length="${length}" radius="${radius}"/>
                        </geometry>
                </visual>  
                <collision>
                        <geometry>
                                <cylinder length="${length}" radius="${radius}"/>
                        </geometry>
                </collision>                    
                <inertial>
                        <mass value="${mass}" />
                        <inertia ixx="1.0" ixy="0.0" ixz="0.0"
                                 iyy="1.0" iyz="0.0"
                                 izz="1.0" />
                </inertial>
        </link>
                <gazebo reference="${link_name}${link_number}">
                        <material>Gazebo/${color}</material>
                </gazebo>
</xacro:macro>
        
<xacro:macro name="joint_description" params="joint_number parent_link child_link">
        <joint name="j${joint_number}" type="revolute">
                <limit effort="${effort}" velocity="${velocity}" lower="${lower}" upper="${upper}"/>
                <parent link="${link_name}${parent_link}"/>
                <child link="${link_name}${child_link}"/>
                <origin xyz="0 0 ${length}"/>
                <axis xyz= "${axis_x} ${axis_y} ${axis_z}"/>
                <dynamics damping="${damping}" friction="${friction}"/>
        </joint>
</xacro:macro>

<xacro:link_description link_number="1" color="Blue"/>
<xacro:link_description link_number="2" color="Red"/>
<xacro:joint_description joint_number="1" parent_link="1" child_link="2" />



</robot>
