<?xml version='1.0' encoding='utf-8'?>
<robot name="rope">
  <link name="rope_seg_1">
    <visual>
      <geometry>
        <cylinder length="0.05" radius="0.01" />
      </geometry>
    </visual>
    <collision>
      <geometry>
        <cylinder length="0.051" radius="0.011" />
      </geometry>
    </collision>
    <inertial>
      <mass value="0.01" />
      <inertia ixx="1.0" ixy="0.0" ixz="0.0" iyy="1.0" iyz="0.0" izz="1.0" />
    </inertial>
  </link>
  <gazebo reference="rope_seg_1">
    <material>Gazebo/WoodFloor</material>
    <selfCollide>true</selfCollide>
  </gazebo>
<link name="rope_seg_2">
    <visual>
      <geometry>
        <cylinder length="0.05" radius="0.01" />
      </geometry>
    </visual>
    <collision>
      <geometry>
        <cylinder length="0.051" radius="0.011" />
      </geometry>
    </collision>
    <inertial>
      <mass value="0.01" />
      <inertia ixx="1.0" ixy="0.0" ixz="0.0" iyy="1.0" iyz="0.0" izz="1.0" />
    </inertial>
  </link>
  <gazebo reference="rope_seg_2">
    <material>Gazebo/WoodFloor</material>
    <selfCollide>true</selfCollide>
  </gazebo>
<joint name="j_1" type="revolute">
    <limit effort="5" lower="-0.785" upper="0.785" velocity="6.28" />
    <parent link="rope_seg_1" />
    <child link="rope_seg_2" />
    <origin xyz="0 0 0.05" />
    <axis xyz="1 1 1" />
    <dynamics damping="1.0" friction="1.0" />
  </joint>
<link name="rope_seg_3">
    <visual>
      <geometry>
        <cylinder length="0.05" radius="0.01" />
      </geometry>
    </visual>
    <collision>
      <geometry>
        <cylinder length="0.051" radius="0.011" />
      </geometry>
    </collision>
    <inertial>
      <mass value="0.01" />
      <inertia ixx="1.0" ixy="0.0" ixz="0.0" iyy="1.0" iyz="0.0" izz="1.0" />
    </inertial>
  </link>
  <gazebo reference="rope_seg_3">
    <material>Gazebo/WoodFloor</material>
    <selfCollide>true</selfCollide>
  </gazebo>
<joint name="j_2" type="revolute">
    <limit effort="5" lower="-0.785" upper="0.785" velocity="6.28" />
    <parent link="rope_seg_2" />
    <child link="rope_seg_3" />
    <origin xyz="0 0 0.05" />
    <axis xyz="1 1 1" />
    <dynamics damping="1.0" friction="1.0" />
  </joint>
<link name="rope_seg_4">
    <visual>
      <geometry>
        <cylinder length="0.05" radius="0.01" />
      </geometry>
    </visual>
    <collision>
      <geometry>
        <cylinder length="0.051" radius="0.011" />
      </geometry>
    </collision>
    <inertial>
      <mass value="0.01" />
      <inertia ixx="1.0" ixy="0.0" ixz="0.0" iyy="1.0" iyz="0.0" izz="1.0" />
    </inertial>
  </link>
  <gazebo reference="rope_seg_4">
    <material>Gazebo/WoodFloor</material>
    <selfCollide>true</selfCollide>
  </gazebo>
<joint name="j_3" type="revolute">
    <limit effort="5" lower="-0.785" upper="0.785" velocity="6.28" />
    <parent link="rope_seg_3" />
    <child link="rope_seg_4" />
    <origin xyz="0 0 0.05" />
    <axis xyz="1 1 1" />
    <dynamics damping="1.0" friction="1.0" />
  </joint>
<link name="rope_seg_5">
    <visual>
      <geometry>
        <cylinder length="0.05" radius="0.01" />
      </geometry>
    </visual>
    <collision>
      <geometry>
        <cylinder length="0.051" radius="0.011" />
      </geometry>
    </collision>
    <inertial>
      <mass value="0.01" />
      <inertia ixx="1.0" ixy="0.0" ixz="0.0" iyy="1.0" iyz="0.0" izz="1.0" />
    </inertial>
  </link>
  <gazebo reference="rope_seg_5">
    <material>Gazebo/WoodFloor</material>
    <selfCollide>true</selfCollide>
  </gazebo>
<joint name="j_4" type="revolute">
    <limit effort="5" lower="-0.785" upper="0.785" velocity="6.28" />
    <parent link="rope_seg_4" />
    <child link="rope_seg_5" />
    <origin xyz="0 0 0.05" />
    <axis xyz="1 1 1" />
    <dynamics damping="1.0" friction="1.0" />
  </joint>
<link name="rope_seg_6">
    <visual>
      <geometry>
        <cylinder length="0.05" radius="0.01" />
      </geometry>
    </visual>
    <collision>
      <geometry>
        <cylinder length="0.051" radius="0.011" />
      </geometry>
    </collision>
    <inertial>
      <mass value="0.01" />
      <inertia ixx="1.0" ixy="0.0" ixz="0.0" iyy="1.0" iyz="0.0" izz="1.0" />
    </inertial>
  </link>
  <gazebo reference="rope_seg_6">
    <material>Gazebo/WoodFloor</material>
    <selfCollide>true</selfCollide>
  </gazebo>
<joint name="j_5" type="revolute">
    <limit effort="5" lower="-0.785" upper="0.785" velocity="6.28" />
    <parent link="rope_seg_5" />
    <child link="rope_seg_6" />
    <origin xyz="0 0 0.05" />
    <axis xyz="1 1 1" />
    <dynamics damping="1.0" friction="1.0" />
  </joint>
<link name="rope_seg_7">
    <visual>
      <geometry>
        <cylinder length="0.05" radius="0.01" />
      </geometry>
    </visual>
    <collision>
      <geometry>
        <cylinder length="0.051" radius="0.011" />
      </geometry>
    </collision>
    <inertial>
      <mass value="0.01" />
      <inertia ixx="1.0" ixy="0.0" ixz="0.0" iyy="1.0" iyz="0.0" izz="1.0" />
    </inertial>
  </link>
  <gazebo reference="rope_seg_7">
    <material>Gazebo/WoodFloor</material>
    <selfCollide>true</selfCollide>
  </gazebo>
<joint name="j_6" type="revolute">
    <limit effort="5" lower="-0.785" upper="0.785" velocity="6.28" />
    <parent link="rope_seg_6" />
    <child link="rope_seg_7" />
    <origin xyz="0 0 0.05" />
    <axis xyz="1 1 1" />
    <dynamics damping="1.0" friction="1.0" />
  </joint>
<link name="rope_seg_8">
    <visual>
      <geometry>
        <cylinder length="0.05" radius="0.01" />
      </geometry>
    </visual>
    <collision>
      <geometry>
        <cylinder length="0.051" radius="0.011" />
      </geometry>
    </collision>
    <inertial>
      <mass value="0.01" />
      <inertia ixx="1.0" ixy="0.0" ixz="0.0" iyy="1.0" iyz="0.0" izz="1.0" />
    </inertial>
  </link>
  <gazebo reference="rope_seg_8">
    <material>Gazebo/WoodFloor</material>
    <selfCollide>true</selfCollide>
  </gazebo>
<joint name="j_7" type="revolute">
    <limit effort="5" lower="-0.785" upper="0.785" velocity="6.28" />
    <parent link="rope_seg_7" />
    <child link="rope_seg_8" />
    <origin xyz="0 0 0.05" />
    <axis xyz="1 1 1" />
    <dynamics damping="1.0" friction="1.0" />
  </joint>
<link name="rope_seg_9">
    <visual>
      <geometry>
        <cylinder length="0.05" radius="0.01" />
      </geometry>
    </visual>
    <collision>
      <geometry>
        <cylinder length="0.051" radius="0.011" />
      </geometry>
    </collision>
    <inertial>
      <mass value="0.01" />
      <inertia ixx="1.0" ixy="0.0" ixz="0.0" iyy="1.0" iyz="0.0" izz="1.0" />
    </inertial>
  </link>
  <gazebo reference="rope_seg_9">
    <material>Gazebo/WoodFloor</material>
    <selfCollide>true</selfCollide>
  </gazebo>
<joint name="j_8" type="revolute">
    <limit effort="5" lower="-0.785" upper="0.785" velocity="6.28" />
    <parent link="rope_seg_8" />
    <child link="rope_seg_9" />
    <origin xyz="0 0 0.05" />
    <axis xyz="1 1 1" />
    <dynamics damping="1.0" friction="1.0" />
  </joint>
<link name="rope_seg_10">
    <visual>
      <geometry>
        <cylinder length="0.05" radius="0.01" />
      </geometry>
    </visual>
    <collision>
      <geometry>
        <cylinder length="0.051" radius="0.011" />
      </geometry>
    </collision>
    <inertial>
      <mass value="0.01" />
      <inertia ixx="1.0" ixy="0.0" ixz="0.0" iyy="1.0" iyz="0.0" izz="1.0" />
    </inertial>
  </link>
  <gazebo reference="rope_seg_10">
    <material>Gazebo/WoodFloor</material>
    <selfCollide>true</selfCollide>
  </gazebo>
<joint name="j_9" type="revolute">
    <limit effort="5" lower="-0.785" upper="0.785" velocity="6.28" />
    <parent link="rope_seg_9" />
    <child link="rope_seg_10" />
    <origin xyz="0 0 0.05" />
    <axis xyz="1 1 1" />
    <dynamics damping="1.0" friction="1.0" />
  </joint>
</robot>